Workbook
Name ADJLAttributesDimensionsColumn: AuxAttributesByDimension!$AC$2:$AC$18
Name ADJLDimensionsClassColumn: AuxDimensionsByClass!$F$2:$F$9
Name ADJLMetricsClassColumn: AuxMetricsByClass!$A$2
Name ADJNAttributesDimensionsColumn: AuxAttributesByDimension!$AB$2:$AB$18
Name ADJNDimensionsClassColumn: AuxDimensionsByClass!$G$2:$G$9
Name ADJNMetricsClassColumn: AuxMetricsByClass!$B$2
Name AggregationsOptionsList: AuxData!$H$2:$H$5
Name AltaiaTypeOptionsList: AuxData!$C$2:$C$5
Name AttributesData1FromDimensions: '4. Dimensions & Entities'!$B$35:$B$428
Name AttributesData2FromDimensions: '4. Dimensions & Entities'!$F$35:$J$428
Name AttributesDataListAux: AuxData!$AC$2:$AC$2
Name AttributesList: '4. Dimensions & Entities'!$F$35:$F$428
Name AttributesListLabelAux: AuxData!$AC$1
Name AttributesLogicalPhysicalDataListAux: AuxData!$AC$2:$AD$469
Name BusyHourConsolidationOptionsList: AuxData!$J$2:$J$7
Name Cell_CoverageAttributesDimensionsColumn: AuxAttributesByDimension!#REF!
Name Cell_INFOAttributesDimensionsColumn: AuxAttributesByDimension!#REF!
Name Cell_OperatorAttributesDimensionsColumn: AuxAttributesByDimension!#REF!
Name Cell_RadioAttributesDimensionsColumn: AuxAttributesByDimension!#REF!
Name CellAttributesDimensionsColumn: AuxAttributesByDimension!$AA$2:$AA$17
Name CellDimensionsClassColumn: AuxDimensionsByClass!$E$2:$E$9
Name CellMetricsClassColumn: AuxMetricsByClass!$C$2
Name ChartScaleTypeOptionsList: AuxData!$Q$2:$Q$3
Name ChartTypeOptionsList: AuxData!$P$2:$P$7
Name ClassesByDimensionListAux: AuxData!$AB$1
Name ClassesByMetricsListAux: AuxData!$AI$1
Name ClassesDataListAux: AuxData!$AF$2:$AF$17
Name ClassesLabelBusMatrix: '4. BUS Matrix'!$B$4
Name ClassesLabelMetricsSheet: '5. Metrics'!$B$4
Name ClassesList: '4. BUS Matrix'!$B$14:$B$28
Name ClassesListLabelAux: AuxData!$AF$1
Name ClassesPhysicalDataListAux: AuxData!$AF$2:$AG$17
Name ClassOfMetricDataList: AuxData!$AI$2:$AJ$2
Name DA_R5G_Cell_COVERAGEAttributesDimensionsColumn: AuxAttributesByDimension!$Z$2:$Z$3
Name DA_R5G_Cell_OperatorAttributesDimensionsColumn: AuxAttributesByDimension!$Y$2:$Y$3
Name DA_R5G_Cell_RadioAttributesDimensionsColumn: AuxAttributesByDimension!$X$2:$X$3
Name DA_R5G_gNodeB_COORDINATESAttributesDimensionsColumn: AuxAttributesByDimension!$W$2:$W$3
Name DA_R5G_gNodeB_GEOGRAPHYAttributesDimensionsColumn: AuxAttributesByDimension!$V$2:$V$3
Name DA_R5G_HUA_gNodeB_COORDAttributesDimensionsColumn: AuxAttributesByDimension!$U$2:$U$3
Name DA_R5G_HUA_gNodeB_GEOAttributesDimensionsColumn: AuxAttributesByDimension!$T$2:$T$8
Name DA_R5G_HUA_Site_Add_INFOAttributesDimensionsColumn: AuxAttributesByDimension!$S$2:$S$5
Name DA_R5G_HUA_SITE_OPERAttributesDimensionsColumn: AuxAttributesByDimension!$R$2
Name DA_R5G_MUNICIPIO_Add_InfoAttributesDimensionsColumn: AuxAttributesByDimension!$Q$2
Name DA_R5G_Site_ADD_INFOAttributesDimensionsColumn: AuxAttributesByDimension!$P$2:$P$3
Name DashboardDescriptionLabelDashboardsSheet: '6. Dashboards'!$C$4
Name DashboardNameLabelDashboardsSheet: '6. Dashboards'!$B$4
Name DBN0DataListAux: AuxData!$V$2:$V$106
Name DBN0LabelListAux: AuxData!$V$1
Name DescriptionLabelGlossarySheet: '2. Glossary'!$D$4
Name DimensionEntityAttributesDescriptionLabelDimensionsSheet: '4. Dimensions & Entities'!$H$4
Name DimensionEntityAttributesLabelDimensionsSheet: '4. Dimensions & Entities'!$F$4
Name DimensionEntityDescriptionLabelDimensionsSheet: '4. Dimensions & Entities'!$E$4
Name DimensionEntityLabelDimensionsSheet: '4. Dimensions & Entities'!$C$4
Name DimensionsByClassListAux: AuxData!$AE$1
Name DimensionsDataListAux: AuxData!$Z$2:$Z$12
Name DimensionsLabelBusMatrix: '4. BUS Matrix'!$H$4
Name DimensionsLabelDimensions: '4. Dimensions & Entities'!$B$4
Name DimensionsList: '4. BUS Matrix'!$J$4:$U$4
Name DimensionsListLabelAux: AuxData!$Z$1
Name DimensionsTypeOptionsList: AuxData!$S$2:$S$3

Sheet 0. Info Pack
B2: 0. Info Pack
B4: Information
B5: Name
B6: Objective
B7: KPI/KQI
B11: Version History
B12: Version | D12: Date | E12: Responsible | F12: Comments
B13: 1.0 | C13: Edition:
C14: Revision:
C15: Approval:
C16: Edition:
C17: Revision:
C18: Approval:
C19: Edition:
C20: Revision:
C21: Approval:
C22: Edition:
C23: Revision:
C24: Approval:

Sheet 1. Help Pack
B2: 1. Help Pack
B4: General Information
C6: Criação de nova linha
C7: A criação de uma nova linha deve ser sempre realizada com base na cópia de uma linha já existente.
C9: Células com valores prédefinidos
C10: Algumas células apenas permitem a inserção de valores prédefinidos com base no Altaia ou com base na informação já existente no ficheiro. Caso tente colocar um valor que não conste na lista, será apresentada uma mensagem de erro.
C12: Células preenchidas automaticamente
C13: Algumas células são preenchidas automaticamente com base em informação já existente no ficheiro. Estas células são assinaladas com uma cor de fundo diferente (ver lengenda).
C15: Legenda de cores
D17: Dados apenas necessários na fase de definição do modelo físico
D18: Dados preenchidos automaticamente com base na informação já inserida noutra sheet
B22: ='0. Info Pack'!$B$2 -> 0. Info Pack
C24: Description
C27: Column Name | D27: Column Description | E27: ???
C28: ='0. Info Pack'!B5 -> Name
C29: ='0. Info Pack'!B6 -> Objective
C30: ='0. Info Pack'!B7 -> KPI/KQI
C31: ='0. Info Pack'!B12 -> Version
C32: ='0. Info Pack'!D12 -> Date
C33: ='0. Info Pack'!E12 -> Responsible
C34: ='0. Info Pack'!F12 -> Comments
B36: ='2. Glossary'!$B$2 -> 2. Glossary
C38: Description
C41: Column Name | D41: Column Description | E41: ???
C42: ='2. Glossary'!$B$4 -> Type
C43: ='2. Glossary'!$C$4 -> Name
C44: ='2. Glossary'!$D$4 -> Description
B46: ='3. Data Sources'!$B$2 -> 3. Data Sources
C48: Description
C51: Column Name | D51: Column Description | E51: ???
C52: =SourcesLabelDataSource -> Inventory Name
C53: ='3. Data Sources'!$D$4 -> Schema
C54: ='3. Data Sources'!$G$4 -> Tech
C55: ='3. Data Sources'!$K$4 -> Description
C56: ='3. Data Sources'!$L$4 -> Type
C57: ='3. Data Sources'!$M$4 -> Method
C58: ='3. Data Sources'!$N$4 -> Period
C59: ='3. Data Sources'!$O$4 -> Delay
C60: ='3. Data Sources'!$P$4 -> Vendor
C61: ='3. Data Sources'!$Q$4 -> Technology/Version
...

Sheet 2. Glossary
B2: 2. Glossary
B4: Type | C4: Name | D4: Description
B5: Source | C5: ENR_RADIO_5G_CELLS
B6: Source | C6: ENR_RADIO_4G5G_HUA_IPPATH | D6: Usar as tabelas já disponiveis no 4G
B7: Source | C7: ENR_RADIO_4G5G_HUA_SCTP | D7: Usar as tabelas já disponiveis no 4G
B8: Source | C8: ENR_RADIO_5G_GNODEB
B9: Source | C9: ENR_OPERATORS
B10: Source | C10: ENR_RADIO_5G_SNSSAI
B11: Source | C11: V_ENR_RADIO_4G_CELLS | D11: View sobre a tabela de celulas 4G para identificação de célula vizinha.
B12: Source | C12: V_ENR_RADIO_5G_CELLS | D12: View sobre a tabela de celulas 5G para identificação de célula vizinha.
B13: Source | C13: T1526726682_5G | D13: GTP-U Measurement
B14: Source | C14: T1542455297_5G | D14: Ethernet Port Measurement
B15: Source | C15: T1542455302_5G
B16: Source | C16: T1542455309_5G | D16: OMCH Measurement
B17: Source | C17: T1542455817_5G | D17: SCTP Link Measurement
B18: Source | C18: T1542455821_5G | D18: Ethernet Delay Measurement
B19: Source | C19: T1542455822_5G | D19: Ethernet Loss Measurement
B20: Source | C20: T1593835529_5G | D20: Node Equipment Measurement
B21: Source | C21: T1593835531_5G | D21: BBU Board Load Measurement
B22: Source | C22: T1593835533_5G | D22: Base Station Clock DA Measurement
B23: Source | C23: T1911816242 | D23: PDCP Measurement
B24: Source | C24: T1911816243 | D24: Cell User Quantity Measurement
B25: Source | C25: T1911816244 | D25: NR DU Cell Scheduled User Quantity Measurement
B26: Source | C26: T1911816247 | D26: Throughput and Data Volume Measurement
B27: Source | C27: T1911816249 | D27: PRB Measurement
... B86: Source | C86: T1914437655_5QI1 | D86: DU Cell Network Slice 5QI RLC Measurement
B87: Source | C87: T1914438708_5QI1
B88: Source | C88: T1911816416_5QI5 | D88: Cell 5QI PDCP Measurement
B89: Source | C89: T1911816418_5QI5 | D89: 5QI QoS Flow Setup Measurement
B90: Source | C90: T1911816419_5QI5 | D90: 5QI QoS Flow Release Measurement
B91: Source | C91: T1911816422_5QI5 | D91: DU Cell 5QI Traffic Measurement
B92: Source | C92: T1911816852_5QI5 | D92: Cell Operator 5QI PDCP Measurement
B93: Source | C93: T1911816853_5QI5 | D93: DU Cell Operator 5QI Traffic Measurement
B94: Source | C94: T1911816856_5QI5 | D94: 5QI QoS Flow Measurement per Operator
B95: Source | C95: T1911817157_5QI5 | D95: 5QI-based Outgoing Intra-RAT Handover Measurement
B96: Source | C96: T1911817158_5QI5 | D96: 5QI-based Outgoing Intra-RAT Handover Measurement per Operator
B97: Source | C97: T1914437654_5QI5 | D97: DU Cell Network Slice 5QI-specific Service Quality Measurement
B98: Source | C98: T1914437655_5QI5 | D98: DU Cell Network Slice 5QI RLC Measurement
B99: Source | C99: T1914438708_5QI5
B100: Source | C100: T1911816416_5QI9 | D100: Cell 5QI PDCP Measurement
...

Sheet 3. Data Sources
B2: 3. Data Sources
B4: Inventory Name | C4: Table Name | D4: Schema | E4: Table Visible in Metrics | F4: Table Visible in AdHoc | G4: Tech | H4: Change | I4: Filter | J4: Hierarchy | K4: Description | L4: Type | M4: Method | N4: Period | O4: Delay | P4: Vendor | Q4: Technology/Version | R4: Tecnologia/Grupo de Contadores | S4: Table Group
B5: ENR_RADIO_5G_CELLS | C5: ENR_RADIO_5G_CELLS | D5: DBN0_EXT_ENRICH | E5: N | F5: =IF(E5="Y","Y","") | L5: Enrichment Table | M5: Automático | N5: 1 Day | O5: 2 Hours | R5: SRAN/RAN | S5: Tabelas_HUA_R5G
B6: ENR_RADIO_4G5G_HUA_IPPATH | C6: ENR_RADIO_4G5G_HUA_IPPATH | D6: DBN0_EXT_ENRICH | E6: N | F6: =IF(E6="Y","Y","") | K6: Usar as tabelas já disponiveis no 4G | L6: Enrichment Table | M6: Automático | N6: 1 Day | O6: 2 Hours | R6: SRAN/RAN | S6: Tabelas_HUA_R5G
B7: ENR_RADIO_4G5G_HUA_SCTP | C7: ENR_RADIO_4G5G_HUA_SCTP | D7: DBN0_EXT_ENRICH | E7: N | F7: =IF(E7="Y","Y","") | K7: Usar as tabelas já disponiveis no 4G | L7: Enrichment Table | M7: Automático | N7: 1 Day | O7: 2 Hours | R7: SRAN/RAN | S7: Tabelas_HUA_R5G
B8: ENR_RADIO_5G_GNODEB | C8: ENR_RADIO_5G_GNODEB | D8: DBN0_EXT_ENRICH | E8: N | F8: =IF(E8="Y","Y","") | L8: Enrichment Table | M8: Automático | N8: 1 Day | O8: 2 Hours | R8: SRAN/RAN | S8: Tabelas_HUA_R5G
B9: ENR_OPERATORS | C9: ENR_OPERATORS | D9: DBN0_EXT_ENRICH | E9: N | F9: =IF(E9="Y","Y","") | L9: Enrichment Table | M9: Automático | N9: 1 Day | O9: 2 Hours | R9: SRAN/RAN | S9: Tabelas_HUA_R5G
B10: ENR_RADIO_5G_SNSSAI | C10: ENR_RADIO_5G_SNSSAI | D10: DBN0_EXT_ENRICH | E10: N | L10: Enrichment Table | M10: Automático | N10: 1 Day | O10: 2 Hours | R10: SRAN/RAN | S10: Tabelas_HUA_R5G
B11: V_ENR_RADIO_4G_CELLS | C11: ENR_RADIO_CELLS_4G | D11: DBN0_EXT_ENRICH | E11: N | F11: =IF(E11="Y","Y","") | K11: View sobre a tabela de celulas 4G para identificação de célula vizinha. | L11: Enrichment Table | M11: Automático | N11: 1 Day | O11: 2 Hours | R11: SRAN/RAN | S11: Tabelas_HUA_R5G
B12: V_ENR_RADIO_5G_CELLS | C12: ENR_RADIO_5G_CELLS | D12: DBN0_EXT_ENRICH | E12: N | F12: =IF(E12="Y","Y","") | K12: View sobre a tabela de celulas 5G para identificação de célula vizinha. | L12: Enrichment Table | M12: Automático | N12: 1 Day | O12: 2 Hours | R12: SRAN/RAN | S12: Tabelas_HUA_R5G
B13: T1526726682_5G | C13: T1526726682 | D13: DBN0_HUA_RAN | E13: Y | F13: =IF(E13="Y","Y","") -> Y | G13: R4G5G | K13: GTP-U Measurement | L13: DBN0 Table | M13: Ficheiro XML | N13: 15 Minutes | O13: 1 Hour | P13: Huawei | Q13: 20.1 | R13: SRAN/RAN | S13: Tabelas_HUA_R5G
B14: T1542455297_5G | C14: T1542455297 | D14: DBN0_HUA_RAN | E14: Y | F14: =IF(E14="Y","Y","") -> Y | G14: R2G3G4G5G | K14: Ethernet Port Measurement | L14: DBN0 Table | M14: Ficheiro XML | N14: 15 Minutes | O14: 1 Hour | P14: Huawei | Q14: 20.1 | R14: SRAN/RAN | S14: Tabelas_HUA_R5G
B15: T1542455302_5G | C15: T1542455302 | D15: DBN0_HUA_RAN | E15: Y | F15: =IF(E15="Y","Y","") -> Y | L15: DBN0 Table | M15: Ficheiro XML | N15: 15 Minutes | O15: 1 Hour | P15: Huawei | Q15: 20.1 | R15: SRAN/RAN | S15: Tabelas_HUA_R5G
B16: T1542455309_5G | C16: T1542455309 | D16: DBN0_HUA_RAN | E16: Y | F16: =IF(E16="Y","Y","") -> Y | G16: R2G3G4G5G | K16: OMCH Measurement | L16: DBN0 Table | M16: Ficheiro XML | N16: 15 Minutes | O16: 1 Hour | P16: Huawei | Q16: 20.1 | R16: SRAN/RAN | S16: Tabelas_HUA_R5G
B17: T1542455817_5G | C17: T1542455817 | D17: DBN0_HUA_RAN | E17: Y | F17: =IF(E17="Y","Y","") -> Y | G17: R2G3G4G5G | K17: SCTP Link Measurement | L17: DBN0 Table | M17: Ficheiro XML | N17: 15 Minutes | O17: 1 Hour | P17: Huawei | Q17: 20.1 | R17: SRAN/RAN | S17: Tabelas_HUA_R5G
B18: T1542455821_5G | C18: T1542455821 | D18: DBN0_HUA_RAN | E18: Y | F18: =IF(E18="Y","Y","") -> Y | G18: R2G3G4G5G | K18: Ethernet Delay Measurement | L18: DBN0 Table | M18: Ficheiro XML | N18: 15 Minutes | O18: 1 Hour | P18: Huawei | Q18: 20.1 | R18: SRAN/RAN | S18: Tabelas_HUA_R5G
B19: T1542455822_5G | C19: T1542455822 | D19: DBN0_HUA_RAN | E19: Y | F19: =IF(E19="Y","Y","") -> Y | G19: R2G3G4G5G | K19: Ethernet Loss Measurement | L19: DBN0 Table | M19: Ficheiro XML | N19: 15 Minutes | O19: 1 Hour | P19: Huawei | Q19: 20.1 | R19: SRAN/RAN | S19: Tabelas_HUA_R5G
B20: T1593835529_5G | C20: T1593835529 | D20: DBN0_HUA_RAN | E20: Y | F20: =IF(E20="Y","Y","") -> Y | G20: R2G3G4G5G | K20: Node Equipment Measurement | L20: DBN0 Table | M20: Ficheiro XML | N20: 15 Minutes | O20: 1 Hour | P20: Huawei | Q20: 20.1 | R20: SRAN/RAN | S20: Tabelas_HUA_R5G
B21: T1593835531_5G | C21: T1593835531 | D21: DBN0_HUA_RAN | E21: Y | F21: =IF(E21="Y","Y","") -> Y | G21: R2G3G4G5G | K21: BBU Board Load Measurement | L21: DBN0 Table | M21: Ficheiro XML | N21: 15 Minutes | O21: 1 Hour | P21: Huawei | Q21: 20.1 | R21: SRAN/RAN | S21: Tabelas_HUA_R5G
B22: T1593835533_5G | C22: T1593835533 | D22: DBN0_HUA_RAN | E22: Y | F22: =IF(E22="Y","Y","") -> Y | G22: R2G3G4G5G | K22: Base Station Clock DA Measurement | L22: DBN0 Table | M22: Ficheiro XML | N22: 15 Minutes | O22: 1 Hour | P22: Huawei | Q22: 20.1 | R22: SRAN/RAN | S22: Tabelas_HUA_R5G
B23: T1911816242 | C23: T1911816242 | D23: DBN0_HUA_RAN | E23: Y | F23: =IF(E23="Y","Y","") -> Y | G23: R5G | H23: New Counters /Attributes | K23: PDCP Measurement | L23: DBN0 Table | M23: Ficheiro XML | N23: 15 Minutes | O23: 1 Hour | P23: Huawei | Q23: 20.1 | R23: SRAN/RAN | S23: Tabelas_HUA_R5G
B24: T1911816243 | C24: T1911816243 | D24: DBN0_HUA_RAN | E24: Y | F24: =IF(E24="Y","Y","") -> Y | G24: R5G | H24: New Counters /Attributes | K24: Cell User Quantity Measurement | L24: DBN0 Table | M24: Ficheiro XML | N24: 15 Minutes | O24: 1 Hour | P24: Huawei | Q24: 20.1 | R24: SRAN/RAN | S24: Tabelas_HUA_R5G
B25: T1911816244 | C25: T1911816244 | D25: DBN0_HUA_RAN | E25: Y | F25: =IF(E25="Y","Y","") -> Y | G25: R5G | H25: New Counters /Attributes | K25: NR DU Cell Scheduled User Quantity Measurement | L25: DBN0 Table | M25: Ficheiro XML | N25: 15 Minutes | O25: 1 Hour | P25: Huawei | Q25: 20.1 | R25: SRAN/RAN | S25: Tabelas_HUA_R5G
B26: T1911816247 | C26: T1911816247 | D26: DBN0_HUA_RAN | E26: Y | F26: =IF(E26="Y","Y","") -> Y | G26: R5G | H26: New Counters /Attributes | K26: Throughput and Data Volume Measurement | L26: DBN0 Table | M26: Ficheiro XML | N26: 15 Minutes | O26: 1 Hour | P26: Huawei | Q26: 20.1 | R26: SRAN/RAN | S26: Tabelas_HUA_R5G
B27: T1911816249 | C27: T1911816249 | D27: DBN0_HUA_RAN | E27: Y | F27: =IF(E27="Y","Y","") -> Y | G27: R5G | H27: New Counters /Attributes | K27: PRB Measurement | L27: DBN0 Table | M27: Ficheiro XML | N27: 15 Minutes | O27: 1 Hour | P27: Huawei | Q27: 20.1 | R27: SRAN/RAN | S27: Tabelas_HUA_R5G
B28: T1911816251 | C28: T1911816251 | D28: DBN0_HUA_RAN | E28: Y | F28: =IF(E28="Y","Y","") -> Y | G28: R5G | H28: New Counters /Attributes | K28: MAC Measurement | L28: DBN0 Table | M28: Ficheiro XML | N28: 15 Minutes | O28: 1 Hour | P28: Huawei | Q28: 20.1 | R28: SRAN/RAN | S28: Tabelas_HUA_R5G
B29: T1911816252 | C29: T1911816252 | D29: DBN0_HUA_RAN | E29: Y | F29: =IF(E29="Y","Y","") -> Y | G29: R5G | K29: MCS Measurement | L29: DBN0 Table | M29: Ficheiro XML | N29: 15 Minutes | O29: 1 Hour | P29: Huawei | Q29: 20.1 | R29: SRAN/RAN | S29: Tabelas_HUA_R5G
B30: T1911816253 | C30: T1911816253 | D30: DBN0_HUA_RAN | E30: Y | F30: =IF(E30="Y","Y","") -> Y | G30: R5G | K30: CQI Measurement | L30: DBN0 Table | M30: Ficheiro XML | N30: 15 Minutes | O30: 1 Hour | P30: Huawei | Q30: 20.1 | R30: SRAN/RAN | S30: Tabelas_HUA_R5G
B31: T1911816254 | C31: T1911816254 | D31: DBN0_HUA_RAN | E31: Y | F31: =IF(E31="Y","Y","") -> Y | G31: R5G | K31: Channel Quality Measurement | L31: DBN0 Table | M31: Ficheiro XML | N31: 15 Minutes | O31: 1 Hour | P31: Huawei | Q31: 20.1 | R31: SRAN/RAN | S31: Tabelas_HUA_R5G
B32: T1911816255 | C32: T1911816255 | D32: DBN0_HUA_RAN | E32: Y | F32: =IF(E32="Y","Y","") -> Y | G32: R5G | H32: New Counters /Attributes | K32: Random Access Measurement | L32: DBN0 Table | M32: Ficheiro XML | N32: 15 Minutes | O32: 1 Hour | P32: Huawei | Q32: 20.1 | R32: SRAN/RAN | S32: Tabelas_HUA_R5G
B33: T1911816256 | C33: T1911816256 | D33: DBN0_HUA_RAN | E33: Y | F33: =IF(E33="Y","Y","") -> Y | G33: R5G | H33: New Counters /Attributes | K33: DC Measurement | L33: DBN0 Table | M33: Ficheiro XML | N33: 15 Minutes | O33: 1 Hour | P33: Huawei | Q33: 20.1 | R33: SRAN/RAN | S33: Tabelas_HUA_R5G
B34: T1911816259 | C34: T1911816259 | D34: DBN0_HUA_RAN | E34: Y | F34: =IF(E34="Y","Y","") -> Y | G34: R5G | H34: New Counters /Attributes | K34: DU Cell Algorithm Measurement | L34: DBN0 Table | M34: Ficheiro XML | N34: 15 Minutes | O34: 1 Hour | P34: Huawei | Q34: 20.1 | R34: SRAN/RAN | S34: Tabelas_HUA_R5G
B35: T1911816261 | C35: T1911816261 | D35: DBN0_HUA_RAN | E35: Y | F35: =IF(E35="Y","Y","") -> Y | G35: R5G | H35: New Counters /Attributes | K35: Cell Algorithm Measurement | L35: DBN0 Table | M35: Ficheiro XML | N35: 15 Minutes | O35: 1 Hour | P35: Huawei | Q35: 20.1 | R35: SRAN/RAN | S35: Tabelas_HUA_R5G
B36: T1911816264 | C36: T1911816264 | D36: DBN0_HUA_RAN | E36: Y | F36: =IF(E36="Y","Y","") -> Y | G36: R5G | K36: Cell CA Measurement | L36: DBN0 Table | M36: Ficheiro XML | N36: 15 Minutes | O36: 1 Hour | P36: Huawei | Q36: 20.1 | R36: SRAN/RAN | S36: Tabelas_HUA_R5G
B37: T1911816265 | C37: T1911816265 | D37: DBN0_HUA_RAN | E37: Y | F37: =IF(E37="Y","Y","") -> Y | G37: R5G | K37: MIMO Channel Measurement | L37: DBN0 Table | M37: Ficheiro XML | N37: 15 Minutes | O37: 1 Hour | P37: Huawei | Q37: 20.1 | R37: SRAN/RAN | S37: Tabelas_HUA_R5G
B38: T1911816267 | C38: T1911816267 | D38: DBN0_HUA_RAN | E38: Y | F38: =IF(E38="Y","Y","") -> Y | G38: R5G | K38: gNodeB Board User-Plane CPU Measurement | L38: DBN0 Table | M38: Ficheiro XML | N38: 15 Minutes | O38: 1 Hour | P38: Huawei | Q38: 20.1 | R38: SRAN/RAN | S38: Tabelas_HUA_R5G
B39: T1911816269 | C39: T1911816269 | D39: DBN0_HUA_RAN | E39: Y | F39: =IF(E39="Y","Y","") -> Y | G39: R5G | H39: New Counters /Attributes | K39: DU Cell CA Measurement | L39: DBN0 Table | M39: Ficheiro XML | N39: 15 Minutes | O39: 1 Hour | P39: Huawei | Q39: 20.1 | R39: SRAN/RAN | S39: Tabelas_HUA_R5G
B40: T1911816273 | C40: T1911816273 | D40: DBN0_HUA_RAN | E40: Y | F40: =IF(E40="Y","Y","") -> Y | G40: R5G | H40: New Counters /Attributes | K40: Outgoing Intra-RAT Handover Measurement | L40: DBN0 Table | M40: Ficheiro XML | N40: 15 Minutes | O40: 1 Hour | P40: Huawei | Q40: 20.1 | R40: SRAN/RAN | S40: Tabelas_HUA_R5G
B41: T1911816274 | C41: T1911816274 | D41: DBN0_HUA_RAN | E41: Y | F41: =IF(E41="Y","Y","") -> Y | G41: R5G | K41: Cell Service Quality Measurement | L41: DBN0 Table | M41: Ficheiro XML | N41: 15 Minutes | O41: 1 Hour | P41: Huawei | Q41: 20.1 | R41: SRAN/RAN | S41: Tabelas_HUA_R5G
B42: T1911816277 | C42: T1911816277 | D42: DBN0_HUA_RAN | E42: Y | F42: =IF(E42="Y","Y","") -> Y | G42: R5G | H42: New Counters /Attributes | K42: QoS Flow Setup Measurement | L42: DBN0 Table | M42: Ficheiro XML | N42: 15 Minutes | O42: 1 Hour | P42: Huawei | Q42: 20.1 | R42: SRAN/RAN | S42: Tabelas_HUA_R5G
...

Sheet 3. Data Sources Attr & Count
B2: 3. Data Source Attributes & Counters
B4: Source Name | C4: Attribute/Counter Name | D4: Attribute/Counter Physical Name | E4: Data Type | F4: Mediation Type | G4: Metrics Attribute Type | H4: Altaia Attribute Type | I4: TableVisible In Metrics | J4: Attribute Visible in Metrics | K4: Attribute Visible in AdHoc | L4: Description | M4: Example | N4: Comments
B5: ENR_OPERATORS | C5: MCC | D5: MCC | E5: VARCHAR2(256) | F5: ID | G5: ID | H5: =IF(G5="Local Date and Hour","Start Time of Interval",IF(OR(G5="Additional Info",G5="ID"),"Attribute", IF(G5="Constant","Constant",IF(OR(G5="Counter",G5="Incremental/Decremental"),"Counter","")))) -> Attribute | I5: =VLOOKUP(B5,'3. Data Sources'!$B$4:$E$5002,4,0) -> N | J5: =IF(OR(G5="Not Map",G5="Sequential"),"N",IF(TRIM(G5)<>"","Y","")) -> Y | K5: =IF(G5="Constant","N",IF(J5="Y","Y","")) -> Y
B6: ENR_OPERATORS | C6: MNC | D6: MNC | E6: VARCHAR2(256) | F6: ID | G6: ID | H6: =IF(G6="Local Date and Hour","Start Time of Interval",IF(OR(G6="Additional Info",G6="ID"),"Attribute", IF(G6="Constant","Constant",IF(OR(G6="Counter",G6="Incremental/Decremental"),"Counter","")))) -> Attribute | I6: =VLOOKUP(B6,'3. Data Sources'!$B$4:$E$5002,4,0) -> N | J6: =IF(OR(G6="Not Map",G6="Sequential"),"N",IF(TRIM(G6)<>"","Y","")) -> Y | K6: =IF(G6="Constant","N",IF(J6="Y","Y","")) -> Y
B7: ENR_OPERATORS | C7: COUNTRY | D7: COUNTRY | E7: VARCHAR2(256) | F7: - | G7: Not Map | H7: =IF(G7="Local Date and Hour","Start Time of Interval",IF(OR(G7="Additional Info",G7="ID"),"Attribute", IF(G7="Constant","Constant",IF(OR(G7="Counter",G7="Incremental/Decremental"),"Counter","")))) | I7: =VLOOKUP(B7,'3. Data Sources'!$B$4:$E$5002,4,0) -> N | J7: =IF(OR(G7="Not Map",G7="Sequential"),"N",IF(TRIM(G7)<>"","Y","")) -> N | K7: =IF(G7="Constant","N",IF(J7="Y","Y",""))
B8: ENR_OPERATORS | C8: OPERATOR | D8: OPERATOR | E8: VARCHAR2(256) | F8: ID | G8: ID | H8: =IF(G8="Local Date and Hour","Start Time of Interval",IF(OR(G8="Additional Info",G8="ID"),"Attribute", IF(G8="Constant","Constant",IF(OR(G8="Counter",G8="Incremental/Decremental"),"Counter","")))) -> Attribute | I8: =VLOOKUP(B8,'3. Data Sources'!$B$4:$E$5002,4,0) -> N | J8: =IF(OR(G8="Not Map",G8="Sequential"),"N",IF(TRIM(G8)<>"","Y","")) -> Y | K8: =IF(G8="Constant","N",IF(J8="Y","Y","")) -> Y
B9: ENR_OPERATORS | C9: ORIGIN | D9: ORIGIN | E9: VARCHAR2(256) | F9: - | G9: Not Map | H9: =IF(G9="Local Date and Hour","Start Time of Interval",IF(OR(G9="Additional Info",G9="ID"),"Attribute", IF(G9="Constant","Constant",IF(OR(G9="Counter",G9="Incremental/Decremental"),"Counter","")))) | I9: =VLOOKUP(B9,'3. Data Sources'!$B$4:$E$5002,4,0) -> N | J9: =IF(OR(G9="Not Map",G9="Sequential"),"N",IF(TRIM(G9)<>"","Y","")) -> N | K9: =IF(G9="Constant","N",IF(J9="Y","Y",""))
B10: ENR_OPERATORS | C10: PROCESSDATE | D10: PROCESSDATE | E10: TIMESTAMP(3) | F10: - | G10: Not Map | H10: =IF(G10="Local Date and Hour","Start Time of Interval",IF(OR(G10="Additional Info",G10="ID"),"Attribute", IF(G10="Constant","Constant",IF(OR(G10="Counter",G10="Incremental/Decremental"),"Counter","")))) | I10: =VLOOKUP(B10,'3. Data Sources'!$B$4:$E$5002,4,0) -> N | J10: =IF(OR(G10="Not Map",G10="Sequential"),"N",IF(TRIM(G10)<>"","Y","")) -> N | K10: =IF(G10="Constant","N",IF(J10="Y","Y",""))
B11: ENR_RADIO_4G5G_HUA_IPPATH | C11: NE_NAME | D11: NE_NAME | E11: TIMESTAMP(3) | F11: - | G11: ID | H11: =IF(G11="Local Date and Hour","Start Time of Interval",IF(OR(G11="Additional Info",G11="ID"),"Attribute", IF(G11="Constant","Constant",IF(OR(G11="Counter",G11="Incremental/Decremental"),"Counter","")))) -> Attribute | I11: =VLOOKUP(B11,'3. Data Sources'!$B$4:$E$5002,4,0) -> N | J11: =IF(OR(G11="Not Map",G11="Sequential"),"N",IF(TRIM(G11)<>"","Y","")) -> Y | K11: =IF(G11="Constant","N",IF(J11="Y","Y","")) -> Y
B12: ENR_RADIO_4G5G_HUA_IPPATH | C12: ENODEB_NAME | D12: ENODEB_NAME | E12: VARCHAR2(255) | F12: - | G12: ID | H12: =IF(G12="Local Date and Hour","Start Time of Interval",IF(OR(G12="Additional Info",G12="ID"),"Attribute", IF(G12="Constant","Constant",IF(OR(G12="Counter",G12="Incremental/Decremental"),"Counter","")))) -> Attribute | I12: =VLOOKUP(B12,'3. Data Sources'!$B$4:$E$5002,4,0) -> N | J12: =IF(OR(G12="Not Map",G12="Sequential"),"N",IF(TRIM(G12)<>"","Y","")) -> Y | K12: =IF(G12="Constant","N",IF(J12="Y","Y","")) -> Y
B13: ENR_RADIO_4G5G_HUA_IPPATH | C13: IPPATH | D13: IPPATH | E13: VARCHAR2(255) | F13: - | G13: ID | H13: =IF(G13="Local Date and Hour","Start Time of Interval",IF(OR(G13="Additional Info",G13="ID"),"Attribute", IF(G13="Constant","Constant",IF(OR(G13="Counter",G13="Incremental/Decremental"),"Counter","")))) -> Attribute | I13: =VLOOKUP(B13,'3. Data Sources'!$B$4:$E$5002,4,0) -> N | J13: =IF(OR(G13="Not Map",G13="Sequential"),"N",IF(TRIM(G13)<>"","Y","")) -> Y | K13: =IF(G13="Constant","N",IF(J13="Y","Y","")) -> Y
B14: ENR_RADIO_4G5G_HUA_IPPATH | C14: PEERIP | D14: PEERIP | E14: VARCHAR2(255) | F14: - | G14: ID | H14: =IF(G14="Local Date and Hour","Start Time of Interval",IF(OR(G14="Additional Info",G14="ID"),"Attribute", IF(G14="Constant","Constant",IF(OR(G14="Counter",G14="Incremental/Decremental"),"Counter","")))) -> Attribute | I14: =VLOOKUP(B14,'3. Data Sources'!$B$4:$E$5002,4,0) -> N | J14: =IF(OR(G14="Not Map",G14="Sequential"),"N",IF(TRIM(G14)<>"","Y","")) -> Y | K14: =IF(G14="Constant","N",IF(J14="Y","Y","")) -> Y
B15: ENR_RADIO_4G5G_HUA_IPPATH | C15: PEERNAME | D15: PEERNAME | E15: VARCHAR2(255) | F15: - | G15: Additional Info | H15: =IF(G15="Local Date and Hour","Start Time of Interval",IF(OR(G15="Additional Info",G15="ID"),"Attribute", IF(G15="Constant","Constant",IF(OR(G15="Counter",G15="Incremental/Decremental"),"Counter","")))) -> Attribute | I15: =VLOOKUP(B15,'3. Data Sources'!$B$4:$E$5002,4,0) -> N | J15: =IF(OR(G15="Not Map",G15="Sequential"),"N",IF(TRIM(G15)<>"","Y","")) -> Y | K15: =IF(G15="Constant","N",IF(J15="Y","Y","")) -> Y
B16: ENR_RADIO_4G5G_HUA_IPPATH | C16: DATASOURCE | D16: DATASOURCE | E16: VARCHAR2(255) | F16: - | G16: Not Map | H16: =IF(G16="Local Date and Hour","Start Time of Interval",IF(OR(G16="Additional Info",G16="ID"),"Attribute", IF(G16="Constant","Constant",IF(OR(G16="Counter",G16="Incremental/Decremental"),"Counter","")))) | I16: =VLOOKUP(B16,'3. Data Sources'!$B$4:$E$5002,4,0) -> N | J16: =IF(OR(G16="Not Map",G16="Sequential"),"N",IF(TRIM(G16)<>"","Y","")) -> N | K16: =IF(G16="Constant","N",IF(J16="Y","Y",""))
... B51: ENR_RADIO_5G_CELLS | C51: SITE_VERSION | D51: SITE_VERSION | E51: VARCHAR2(256) | F51: ID | G51: ID | H51: =IF(G51="Local Date and Hour","Start Time of Interval",IF(OR(G51="Additional Info",G51="ID"),"Attribute", IF(G51="Constant","Constant",IF(OR(G51="Counter",G51="Incremental/Decremental"),"Counter","")))) -> Attribute | I51: =VLOOKUP(B51,'3. Data Sources'!$B$4:$E$5002,4,0) -> N | J51: =IF(OR(G51="Not Map",G51="Sequential"),"N",IF(TRIM(G51)<>"","Y","")) -> Y | K51: =IF(G51="Constant","N",IF(J51="Y","Y","")) -> Y
B52: ENR_RADIO_5G_CELLS | C52: STATION_CODE | D52: STATION_CODE | E52: VARCHAR(255) | F52: ID | G52: ID | H52: Attribute | I52: =VLOOKUP(B52,'3. Data Sources'!$B$4:$E$5002,4,0) -> N | J52: =IF(OR(G52="Not Map",G52="Sequential"),"N",IF(TRIM(G52)<>"","Y","")) -> Y | K52: =IF(G52="Constant","N",IF(J52="Y","Y","")) -> Y
B53: ENR_RADIO_5G_CELLS | C53: NE_NAME | D53: NE_NAME | E53: VARCHAR(255) | F53: ID | G53: ID | H53: Attribute | I53: =VLOOKUP(B53,'3. Data Sources'!$B$4:$E$5002,4,0) -> N | J53: =IF(OR(G53="Not Map",G53="Sequential"),"N",IF(TRIM(G53)<>"","Y","")) -> Y | K53: =IF(G53="Constant","N",IF(J53="Y","Y","")) -> Y
B54: ENR_RADIO_5G_CELLS | C54: ID_MASTER | D54: ID_MASTER | E54: VARCHAR(255) | F54: ID | G54: ID | H54: Attribute | I54: =VLOOKUP(B54,'3. Data Sources'!$B$4:$E$5002,4,0) -> N | J54: =IF(OR(G54="Not Map",G54="Sequential"),"N",IF(TRIM(G54)<>"","Y","")) -> Y | K54: =IF(G54="Constant","N",IF(J54="Y","Y","")) -> Y
B55: ENR_RADIO_5G_CELLS | C55: SITE_TYPE | D55: SITE_TYPE | E55: VARCHAR2(256) | F55: ID | G55: ID | H55: =IF(G55="Local Date and Hour","Start Time of Interval",IF(OR(G55="Additional Info",G55="ID"),"Attribute", IF(G55="Constant","Constant",IF(OR(G55="Counter",G55="Incremental/Decremental"),"Counter","")))) -> Attribute | I55: =VLOOKUP(B55,'3. Data Sources'!$B$4:$E$5002,4,0) -> N | J55: =IF(OR(G55="Not Map",G55="Sequential"),"N",IF(TRIM(G55)<>"","Y","")) -> Y | K55: =IF(G55="Constant","N",IF(J55="Y","Y","")) -> Y
B56: ENR_RADIO_5G_CELLS | C56: ORIGIN | D56: ORIGIN | E56: VARCHAR2(256) | F56: - | G56: Not Map | H56: =IF(G56="Local Date and Hour","Start Time of Interval",IF(OR(G56="Additional Info",G56="ID"),"Attribute", IF(G56="Constant","Constant",IF(OR(G56="Counter",G56="Incremental/Decremental"),"Counter","")))) | I56: =VLOOKUP(B56,'3. Data Sources'!$B$4:$E$5002,4,0) -> N | J56: =IF(OR(G56="Not Map",G56="Sequential"),"N",IF(TRIM(G56)<>"","Y","")) -> N | K56: =IF(G56="Constant","N",IF(J56="Y","Y",""))
B57: ENR_RADIO_5G_CELLS | C57: PROCESSDATE | D57: PROCESSDATE | E57: TIMESTAMP(3) | F57: - | G57: Not Map | H57: =IF(G57="Local Date and Hour","Start Time of Interval",IF(OR(G57="Additional Info",G57="ID"),"Attribute", IF(G57="Constant","Constant",IF(OR(G57="Counter",G57="Incremental/Decremental"),"Counter","")))) | I57: =VLOOKUP(B57,'3. Data Sources'!$B$4:$E$5002,4,0) -> N | J57: =IF(OR(G57="Not Map",G57="Sequential"),"N",IF(TRIM(G57)<>"","Y","")) -> N | K57: =IF(G57="Constant","N",IF(J57="Y","Y",""))
B58: ENR_RADIO_5G_CELLS | C58: STARTTIME | D58: STARTTIME | E58: VARCHAR2(256) | F58: - | G58: Local Date and Hour | H58: =IF(G58="Local Date and Hour","Start Time of Interval",IF(OR(G58="Additional Info",G58="ID"),"Attribute", IF(G58="Constant","Constant",IF(OR(G58="Counter",G58="Incremental/Decremental"),"Counter","")))) -> Start Time of Interval | I58: =VLOOKUP(B58,'3. Data Sources'!$B$4:$E$5002,4,0) -> N | J58: =IF(OR(G58="Not Map",G58="Sequential"),"N",IF(TRIM(G58)<>"","Y","")) -> Y | K58: =IF(G58="Constant","N",IF(J58="Y","Y","")) -> Y
B59: ENR_RADIO_5G_GNODEB | C59: MOBILE_SITE_NAME | D59: MOBILE_SITE_NAME | E59: VARCHAR2(256) | F59: ID | G59: ID | H59: =IF(G59="Local Date and Hour","Start Time of Interval",IF(OR(G59="Additional Info",G59="ID"),"Attribute", IF(G59="Constant","Constant",IF(OR(G59="Counter",G59="Incremental/Decremental"),"Counter","")))) -> Attribute | I59: =VLOOKUP(B59,'3. Data Sources'!$B$4:$E$5002,4,0) -> N | J59: =IF(OR(G59="Not Map",G59="Sequential"),"N",IF(TRIM(G59)<>"","Y","")) -> Y | K59: =IF(G59="Constant","N",IF(J59="Y","Y","")) -> Y
B60: ENR_RADIO_5G_GNODEB | C60: GNODEB_CN | D60: GNODEB_CN | E60: VARCHAR2(256) | F60: ID | G60: ID | H60: =IF(G60="Local Date and Hour","Start Time of Interval",IF(OR(G60="Additional Info",G60="ID"),"Attribute", IF(G60="Constant","Constant",IF(OR(G60="Counter",G60="Incremental/Decremental"),"Counter","")))) -> Attribute | I60: =VLOOKUP(B60,'3. Data Sources'!$B$4:$E$5002,4,0) -> N | J60: =IF(OR(G60="Not Map",G60="Sequential"),"N",IF(TRIM(G60)<>"","Y","")) -> Y | K60: =IF(G60="Constant","N",IF(J60="Y","Y","")) -> Y
B61: ENR_RADIO_5G_GNODEB | C61: GNODEB_IBGE_ID | D61: GNODEB_IBGE_ID | E61: VARCHAR(256) | F61: ID | G61: ID | H61: =IF(G61="Local Date and Hour","Start Time of Interval",IF(OR(G61="Additional Info",G61="ID"),"Attribute", IF(G61="Constant","Constant",IF(OR(G61="Counter",G61="Incremental/Decremental"),"Counter","")))) -> Attribute | I61: =VLOOKUP(B61,'3. Data Sources'!$B$4:$E$5002,4,0) -> N | J61: =IF(OR(G61="Not Map",G61="Sequential"),"N",IF(TRIM(G61)<>"","Y","")) -> Y | K61: =IF(G61="Constant","N",IF(J61="Y","Y","")) -> Y
B62: ENR_RADIO_5G_GNODEB | C62: GNODEB_LATITUDE | D62: GNODEB_LATITUDE | E62: VARCHAR2(256) | F62: ID | G62: ID | H62: =IF(G62="Local Date and Hour","Start Time of Interval",IF(OR(G62="Additional Info",G62="ID"),"Attribute", IF(G62="Constant","Constant",IF(OR(G62="Counter",G62="Incremental/Decremental"),"Counter","")))) -> Attribute | I62: =VLOOKUP(B62,'3. Data Sources'!$B$4:$E$5002,4,0) -> N | J62: =IF(OR(G62="Not Map",G62="Sequential"),"N",IF(TRIM(G62)<>"","Y","")) -> Y | K62: =IF(G62="Constant","N",IF(J62="Y","Y","")) -> Y
B63: ENR_RADIO_5G_GNODEB | C63: GNODEB_LONGITUDE | D63: GNODEB_LONGITUDE | E63: VARCHAR2(256) | F63: ID | G63: ID | H63: =IF(G63="Local Date and Hour","Start Time of Interval",IF(OR(G63="Additional Info",G63="ID"),"Attribute", IF(G63="Constant","Constant",IF(OR(G63="Counter",G63="Incremental/Decremental"),"Counter","")))) -> Attribute | I63: =VLOOKUP(B63,'3. Data Sources'!$B$4:$E$5002,4,0) -> N | J63: =IF(OR(G63="Not Map",G63="Sequential"),"N",IF(TRIM(G63)<>"","Y","")) -> Y | K63: =IF(G63="Constant","N",IF(J63="Y","Y","")) -> Y
B64: ENR_RADIO_5G_GNODEB | C64: GNODEB_MUNICIPALY | D64: GNODEB_MUNICIPALY | E64: VARCHAR2(256) | F64: ID | G64: ID | H64: =IF(G64="Local Date and Hour","Start Time of Interval",IF(OR(G64="Additional Info",G64="ID"),"Attribute", IF(G64="Constant","Constant",IF(OR(G64="Counter",G64="Incremental/Decremental"),"Counter","")))) -> Attribute | I64: =VLOOKUP(B64,'3. Data Sources'!$B$4:$E$5002,4,0) -> N | J64: =IF(OR(G64="Not Map",G64="Sequential"),"N",IF(TRIM(G64)<>"","Y","")) -> Y | K64: =IF(G64="Constant","N",IF(J64="Y","Y","")) -> Y
B65: ENR_RADIO_5G_GNODEB | C65: GNODEB_NEIGHBORHOOD | D65: GNODEB_NEIGHBORHOOD | E65: VARCHAR2(256) | F65: ID | G65: ID | H65: =IF(G65="Local Date and Hour","Start Time of Interval",IF(OR(G65="Additional Info",G65="ID"),"Attribute", IF(G65="Constant","Constant",IF(OR(G65="Counter",G65="Incremental/Decremental"),"Counter","")))) -> Attribute | I65: =VLOOKUP(B65,'3. Data Sources'!$B$4:$E$5002,4,0) -> N | J65: =IF(OR(G65="Not Map",G65="Sequential"),"N",IF(TRIM(G65)<>"","Y","")) -> Y | K65: =IF(G65="Constant","N",IF(J65="Y","Y","")) -> Y
B66: ENR_RADIO_5G_GNODEB | C66: GNODEB_REGION | D66: GNODEB_REGION | E66: VARCHAR2(256) | F66: ID | G66: ID | H66: =IF(G66="Local Date and Hour","Start Time of Interval",IF(OR(G66="Additional Info",G66="ID"),"Attribute", IF(G66="Constant","Constant",IF(OR(G66="Counter",G66="Incremental/Decremental"),"Counter","")))) -> Attribute | I66: =VLOOKUP(B66,'3. Data Sources'!$B$4:$E$5002,4,0) -> N | J66: =IF(OR(G66="Not Map",G66="Sequential"),"N",IF(TRIM(G66)<>"","Y","")) -> Y | K66: =IF(G66="Constant","N",IF(J66="Y","Y","")) -> Y
... B73: ENR_RADIO_5G_GNODEB | C73: ERB_FISICA | D73: ERB_FISICA | E73: VARCHAR2(256) | F73: ID | G73: ID | H73: =IF(G73="Local Date and Hour","Start Time of Interval",IF(OR(G73="Additional Info",G73="ID"),"Attribute", IF(G73="Constant","Constant",IF(OR(G73="Counter",G73="Incremental/Decremental"),"Counter","")))) -> Attribute | I73: =VLOOKUP(B73,'3. Data Sources'!$B$4:$E$5002,4,0) -> N | J73: =IF(OR(G73="Not Map",G73="Sequential"),"N",IF(TRIM(G73)<>"","Y","")) -> Y | K73: =IF(G73="Constant","N",IF(J73="Y","Y","")) -> Y
B74: ENR_RADIO_5G_GNODEB | C74: NE_NAME | D74: NE_NAME | E74: VARCHAR(255) | F74: ID | G74: ID | H74: Attribute | I74: =VLOOKUP(B74,'3. Data Sources'!$B$4:$E$5002,4,0) -> N | J74: =IF(OR(G74="Not Map",G74="Sequential"),"N",IF(TRIM(G74)<>"","Y","")) -> Y | K74: =IF(G74="Constant","N",IF(J74="Y","Y","")) -> Y
B75: ENR_RADIO_5G_GNODEB | C75: ID_MASTER | D75: ID_MASTER | E75: VARCHAR(256) | F75: ID | G75: ID | H75: =IF(G75="Local Date and Hour","Start Time of Interval",IF(OR(G75="Additional Info",G75="ID"),"Attribute", IF(G75="Constant","Constant",IF(OR(G75="Counter",G75="Incremental/Decremental"),"Counter","")))) -> Attribute | I75: =VLOOKUP(B75,'3. Data Sources'!$B$4:$E$5002,4,0) -> N | J75: =IF(OR(G75="Not Map",G75="Sequential"),"N",IF(TRIM(G75)<>"","Y","")) -> Y | K75: =IF(G75="Constant","N",IF(J75="Y","Y","")) -> Y
B76: ENR_RADIO_5G_GNODEB | C76: SITE_TYPE | D76: SITE_TYPE | E76: VARCHAR2(256) | F76: ID | G76: ID | H76: =IF(G76="Local Date and Hour","Start Time of Interval",IF(OR(G76="Additional Info",G76="ID"),"Attribute", IF(G76="Constant","Constant",IF(OR(G76="Counter",G76="Incremental/Decremental"),"Counter","")))) -> Attribute | I76: =VLOOKUP(B76,'3. Data Sources'!$B$4:$E$5002,4,0) -> N | J76: =IF(OR(G76="Not Map",G76="Sequential"),"N",IF(TRIM(G76)<>"","Y","")) -> Y | K76: =IF(G76="Constant","N",IF(J76="Y","Y","")) -> Y
B77: ENR_RADIO_5G_GNODEB | C77: STARTTIME | D77: STARTTIME | E77: TIMESTAMP(3) | F77: - | G77: Local Date and Hour | H77: =IF(G77="Local Date and Hour","Start Time of Interval",IF(OR(G77="Additional Info",G77="ID"),"Attribute", IF(G77="Constant","Constant",IF(OR(G77="Counter",G77="Incremental/Decremental"),"Counter","")))) -> Start Time of Interval | I77: =VLOOKUP(B77,'3. Data Sources'!$B$4:$E$5002,4,0) -> N | J77: =IF(OR(G77="Not Map",G77="Sequential"),"N",IF(TRIM(G77)<>"","Y","")) -> Y | K77: =IF(G77="Constant","N",IF(J77="Y","Y","")) -> Y
B78: ENR_RADIO_5G_GNODEB | C78: ORIGIN | D78: ORIGIN | E78: VARCHAR2(256) | F78: - | G78: Not Map | H78: =IF(G78="Local Date and Hour","Start Time of Interval",IF(OR(G78="Additional Info",G78="ID"),"Attribute", IF(G78="Constant","Constant",IF(OR(G78="Counter",G78="Incremental/Decremental"),"Counter","")))) | I78: =VLOOKUP(B78,'3. Data Sources'!$B$4:$E$5002,4,0) -> N | J78: =IF(OR(G78="Not Map",G78="Sequential"),"N",IF(TRIM(G78)<>"","Y","")) -> N | K78: =IF(G78="Constant","N",IF(J78="Y","Y",""))
B79: ENR_RADIO_5G_GNODEB | C79: PROCESSDATE | D79: PROCESSDATE | E79: TIMESTAMP(3) | F79: - | G79: Not Map | H79: =IF(G79="Local Date and Hour","Start Time of Interval",IF(OR(G79="Additional Info",G79="ID"),"Attribute", IF(G79="Constant","Constant",IF(OR(G79="Counter",G79="Incremental/Decremental"),"Counter","")))) | I79: =VLOOKUP(B79,'3. Data Sources'!$B$4:$E$5002,4,0) -> N | J79: =IF(OR(G79="Not Map",G79="Sequential"),"N",IF(TRIM(G79)<>"","Y","")) -> N | K79: =IF(G79="Constant","N",IF(J79="Y","Y",""))
B80: ENR_RADIO_5G_SNSSAI | C80: SST | D80: SST | E80: NUMBER | F80: PK | G80: ID | H80: =IF(G80="Local Date and Hour","Start Time of Interval",IF(OR(G80="Additional Info",G80="ID"),"Attribute", IF(G80="Constant","Constant",IF(OR(G80="Counter",G80="Incremental/Decremental"),"Counter","")))) -> Attribute | I80: =VLOOKUP(B80,'3. Data Sources'!$B$4:$E$5002,4,0) -> N | J80: =IF(OR(G80="Not Map",G80="Sequential"),"N",IF(TRIM(G80)<>"","Y","")) -> Y | K80: =IF(G80="Constant","N",IF(J80="Y","Y","")) -> Y
B81: ENR_RADIO_5G_SNSSAI | C81: SD | D81: SD | E81: NUMBER | F81: PK | G81: ID | H81: =IF(G81="Local Date and Hour","Start Time of Interval",IF(OR(G81="Additional Info",G81="ID"),"Attribute", IF(G81="Constant","Constant",IF(OR(G81="Counter",G81="Incremental/Decremental"),"Counter","")))) -> Attribute | I81: =VLOOKUP(B81,'3. Data Sources'!$B$4:$E$5002,4,0) -> N | J81: =IF(OR(G81="Not Map",G81="Sequential"),"N",IF(TRIM(G81)<>"","Y","")) -> Y | K81: =IF(G81="Constant","N",IF(J81="Y","Y","")) -> Y
B82: ENR_RADIO_5G_SNSSAI | C82: SLICENAME | D82: SLICENAME | E82: VARCHAR2(256) | F82: ID | G82: ID | H82: =IF(G82="Local Date and Hour","Start Time of Interval",IF(OR(G82="Additional Info",G82="ID"),"Attribute", IF(G82="Constant","Constant",IF(OR(G82="Counter",G82="Incremental/Decremental"),"Counter","")))) -> Attribute | I82: =VLOOKUP(B82,'3. Data Sources'!$B$4:$E$5002,4,0) -> N | J82: =IF(OR(G82="Not Map",G82="Sequential"),"N",IF(TRIM(G82)<>"","Y","")) -> Y | K82: =IF(G82="Constant","N",IF(J82="Y","Y","")) -> Y
...

Sheet 3. Data Sources Map
B2: 3. Data Sources Map
B4: Enrichment Table Name | C4: Enrichment Attribute Name | D4: Enrichment Attribute Physical Name | E4: DBNO Table Name | F4: DBN0 Attribute Name | G4: DBN0 Attribute Physical Name | H4: Metrics Join Type | I4: Table Visible In Metrics | J4: AdHoc Join Type
B5: ENR_RADIO_5G_GNODEB | C5: NE_NAME | D5: =IF(ISERROR(MATCH(B5&"_"&C5,AuxData!$X:$X,0)),"",IF(LOOKUP(B5&"_"&C5,AuxData!$X:$X,AuxData!$Y:$Y)="","Not defined",LOOKUP(B5&"_"&C5,AuxData!$X:$X,AuxData!$Y:$Y))) -> NE_NAME | E5: T1526726682_5G | F5: Object | G5: =IF(ISERROR(MATCH(E5&"_"&F5,AuxData!$X:$X,0)),"",IF(LOOKUP(E5&"_"&F5,AuxData!$X:$X,AuxData!$Y:$Y)="","Not defined",LOOKUP(E5&"_"&F5,AuxData!$X:$X,AuxData!$Y:$Y))) -> OBJECT | H5: Inner | I5: =IF(ISERROR(MATCH($E5,'3. Data Sources'!$B$5:$B$210,0)),"ERROR",LOOKUP($E5,'3. Data Sources'!$B$5:$B$210,'3. Data Sources'!$E$5:$E$210)) -> Y | J5: Left Outer
B6: ENR_RADIO_5G_GNODEB | C6: NE_NAME | D6: =IF(ISERROR(MATCH(B6&"_"&C6,AuxData!$X:$X,0)),"",IF(LOOKUP(B6&"_"&C6,AuxData!$X:$X,AuxData!$Y:$Y)="","Not defined",LOOKUP(B6&"_"&C6,AuxData!$X:$X,AuxData!$Y:$Y))) -> NE_NAME | E6: T1542455297_5G | F6: Object | G6: =IF(ISERROR(MATCH(E6&"_"&F6,AuxData!$X:$X,0)),"",IF(LOOKUP(E6&"_"&F6,AuxData!$X:$X,AuxData!$Y:$Y)="","Not defined",LOOKUP(E6&"_"&F6,AuxData!$X:$X,AuxData!$Y:$Y))) -> OBJECT | H6: =IF(I6="Y","Inner","") -> Inner | I6: =IF(ISERROR(MATCH($E6,'3. Data Sources'!$B$5:$B$210,0)),"ERROR",LOOKUP($E6,'3. Data Sources'!$B$5:$B$210,'3. Data Sources'!$E$5:$E$210)) -> Y | J6: Left Outer
B7: ENR_RADIO_4G5G_HUA_IPPATH | C7: IPPATH | D7: =IF(ISERROR(MATCH(B7&"_"&C7,AuxData!$X:$X,0)),"",IF(LOOKUP(B7&"_"&C7,AuxData!$X:$X,AuxData!$Y:$Y)="","Not defined",LOOKUP(B7&"_"&C7,AuxData!$X:$X,AuxData!$Y:$Y))) -> IPPATH | E7: T1542455302_5G | F7: IPPATHID | G7: =IF(ISERROR(MATCH(E7&"_"&F7,AuxData!$X:$X,0)),"",IF(LOOKUP(E7&"_"&F7,AuxData!$X:$X,AuxData!$Y:$Y)="","Not defined",LOOKUP(E7&"_"&F7,AuxData!$X:$X,AuxData!$Y:$Y))) -> IPPATHID | H7: =IF(I7="Y","Inner","") -> Inner | I7: =IF(ISERROR(MATCH($E7,'3. Data Sources'!$B$5:$B$210,0)),"ERROR",LOOKUP($E7,'3. Data Sources'!$B$5:$B$210,'3. Data Sources'!$E$5:$E$210)) -> Y | J7: Left Outer
B8: ENR_RADIO_4G5G_HUA_IPPATH | C8: NE_NAME | D8: =IF(ISERROR(MATCH(B8&"_"&C8,AuxData!$X:$X,0)),"",IF(LOOKUP(B8&"_"&C8,AuxData!$X:$X,AuxData!$Y:$Y)="","Not defined",LOOKUP(B8&"_"&C8,AuxData!$X:$X,AuxData!$Y:$Y))) -> NE_NAME | E8: T1542455302_5G | F8: Object | G8: =IF(ISERROR(MATCH(E8&"_"&F8,AuxData!$X:$X,0)),"",IF(LOOKUP(E8&"_"&F8,AuxData!$X:$X,AuxData!$Y:$Y)="","Not defined",LOOKUP(E8&"_"&F8,AuxData!$X:$X,AuxData!$Y:$Y))) -> OBJECT | H8: =IF(I8="Y","Inner","") -> Inner | I8: =IF(ISERROR(MATCH($E8,'3. Data Sources'!$B$5:$B$210,0)),"ERROR",LOOKUP($E8,'3. Data Sources'!$B$5:$B$210,'3. Data Sources'!$E$5:$E$210)) -> Y | J8: Left Outer
B9: ENR_RADIO_5G_GNODEB | C9: NE_NAME | D9: =IF(ISERROR(MATCH(B9&"_"&C9,AuxData!$X:$X,0)),"",IF(LOOKUP(B9&"_"&C9,AuxData!$X:$X,AuxData!$Y:$Y)="","Not defined",LOOKUP(B9&"_"&C9,AuxData!$X:$X,AuxData!$Y:$Y))) -> NE_NAME | E9: T1542455302_5G | F9: Object | G9: =IF(ISERROR(MATCH(E9&"_"&F9,AuxData!$X:$X,0)),"",IF(LOOKUP(E9&"_"&F9,AuxData!$X:$X,AuxData!$Y:$Y)="","Not defined",LOOKUP(E9&"_"&F9,AuxData!$X:$X,AuxData!$Y:$Y))) -> OBJECT | H9: =IF(I9="Y","Inner","") -> Inner | I9: =IF(ISERROR(MATCH($E9,'3. Data Sources'!$B$5:$B$210,0)),"ERROR",LOOKUP($E9,'3. Data Sources'!$B$5:$B$210,'3. Data Sources'!$E$5:$E$210)) -> Y | J9: Left Outer
B10: ENR_RADIO_5G_GNODEB | C10: NE_NAME | D10: =IF(ISERROR(MATCH(B10&"_"&C10,AuxData!$X:$X,0)),"",IF(LOOKUP(B10&"_"&C10,AuxData!$X:$X,AuxData!$Y:$Y)="","Not defined",LOOKUP(B10&"_"&C10,AuxData!$X:$X,AuxData!$Y:$Y))) -> NE_NAME | E10: T1542455309_5G | F10: Object | G10: =IF(ISERROR(MATCH(E10&"_"&F10,AuxData!$X:$X,0)),"",IF(LOOKUP(E10&"_"&F10,AuxData!$X:$X,AuxData!$Y:$Y)="","Not defined",LOOKUP(E10&"_"&F10,AuxData!$X:$X,AuxData!$Y:$Y))) -> OBJECT | H10: =IF(I10="Y","Inner","") -> Inner | I10: =IF(ISERROR(MATCH($E10,'3. Data Sources'!$B$5:$B$210,0)),"ERROR",LOOKUP($E10,'3. Data Sources'!$B$5:$B$210,'3. Data Sources'!$E$5:$E$210)) -> Y | J10: Left Outer
B11: ENR_RADIO_4G5G_HUA_SCTP | C11: LinkNo | D11: =IF(ISERROR(MATCH(B11&"_"&C11,AuxData!$X:$X,0)),"",IF(LOOKUP(B11&"_"&C11,AuxData!$X:$X,AuxData!$Y:$Y)="","Not defined",LOOKUP(B11&"_"&C11,AuxData!$X:$X,AuxData!$Y:$Y))) -> LINKNO | E11: T1542455817_5G | F11: LinkNo | G11: =IF(ISERROR(MATCH(E11&"_"&F11,AuxData!$X:$X,0)),"",IF(LOOKUP(E11&"_"&F11,AuxData!$X:$X,AuxData!$Y:$Y)="","Not defined",LOOKUP(E11&"_"&F11,AuxData!$X:$X,AuxData!$Y:$Y))) -> LINKNO | H11: =IF(I11="Y","Inner","") -> Inner | I11: =IF(ISERROR(MATCH($E11,'3. Data Sources'!$B$5:$B$210,0)),"ERROR",LOOKUP($E11,'3. Data Sources'!$B$5:$B$210,'3. Data Sources'!$E$5:$E$210)) -> Y | J11: Left Outer
B12: ENR_RADIO_4G5G_HUA_SCTP | C12: NE_NAME | D12: =IF(ISERROR(MATCH(B12&"_"&C12,AuxData!$X:$X,0)),"",IF(LOOKUP(B12&"_"&C12,AuxData!$X:$X,AuxData!$Y:$Y)="","Not defined",LOOKUP(B12&"_"&C12,AuxData!$X:$X,AuxData!$Y:$Y))) -> NE_NAME | E12: T1542455817_5G | F12: Object | G12: =IF(ISERROR(MATCH(E12&"_"&F12,AuxData!$X:$X,0)),"",IF(LOOKUP(E12&"_"&F12,AuxData!$X:$X,AuxData!$Y:$Y)="","Not defined",LOOKUP(E12&"_"&F12,AuxData!$X:$X,AuxData!$Y:$Y))) -> OBJECT | H12: =IF(I12="Y","Inner","") -> Inner | I12: =IF(ISERROR(MATCH($E12,'3. Data Sources'!$B$5:$B$210,0)),"ERROR",LOOKUP($E12,'3. Data Sources'!$B$5:$B$210,'3. Data Sources'!$E$5:$E$210)) -> Y | J12: Left Outer
B13: ENR_RADIO_5G_GNODEB | C13: NE_NAME | D13: =IF(ISERROR(MATCH(B13&"_"&C13,AuxData!$X:$X,0)),"",IF(LOOKUP(B13&"_"&C13,AuxData!$X:$X,AuxData!$Y:$Y)="","Not defined",LOOKUP(B13&"_"&C13,AuxData!$X:$X,AuxData!$Y:$Y))) -> NE_NAME | E13: T1542455817_5G | F13: Object | G13: =IF(ISERROR(MATCH(E13&"_"&F13,AuxData!$X:$X,0)),"",IF(LOOKUP(E13&"_"&F13,AuxData!$X:$X,AuxData!$Y:$Y)="","Not defined",LOOKUP(E13&"_"&F13,AuxData!$X:$X,AuxData!$Y:$Y))) -> OBJECT | H13: =IF(I13="Y","Inner","") -> Inner | I13: =IF(ISERROR(MATCH($E13,'3. Data Sources'!$B$5:$B$210,0)),"ERROR",LOOKUP($E13,'3. Data Sources'!$B$5:$B$210,'3. Data Sources'!$E$5:$E$210)) -> Y | J13: Left Outer
B14: ENR_RADIO_5G_GNODEB | C14: NE_NAME | D14: =IF(ISERROR(MATCH(B14&"_"&C14,AuxData!$X:$X,0)),"",IF(LOOKUP(B14&"_"&C14,AuxData!$X:$X,AuxData!$Y:$Y)="","Not defined",LOOKUP(B14&"_"&C14,AuxData!$X:$X,AuxData!$Y:$Y))) -> NE_NAME | E14: T1542455821_5G | F14: Object | G14: =IF(ISERROR(MATCH(E14&"_"&F14,AuxData!$X:$X,0)),"",IF(LOOKUP(E14&"_"&F14,AuxData!$X:$X,AuxData!$Y:$Y)="","Not defined",LOOKUP(E14&"_"&F14,AuxData!$X:$X,AuxData!$Y:$Y))) | H14: =IF(I14="Y","Inner","") -> Inner | I14: =IF(ISERROR(MATCH($E14,'3. Data Sources'!$B$5:$B$210,0)),"ERROR",LOOKUP($E14,'3. Data Sources'!$B$5:$B$210,'3. Data Sources'!$E$5:$E$210)) -> Y | J14: Left Outer
B15: ENR_RADIO_5G_GNODEB | C15: NE_NAME | D15: =IF(ISERROR(MATCH(B15&"_"&C15,AuxData!$X:$X,0)),"",IF(LOOKUP(B15&"_"&C15,AuxData!$X:$X,AuxData!$Y:$Y)="","Not defined",LOOKUP(B15&"_"&C15,AuxData!$X:$X,AuxData!$Y:$Y))) -> NE_NAME | E15: T1542455822_5G | F15: Object | G15: =IF(ISERROR(MATCH(E15&"_"&F15,AuxData!$X:$X,0)),"",IF(LOOKUP(E15&"_"&F15,AuxData!$X:$X,AuxData!$Y:$Y)="","Not defined",LOOKUP(E15&"_"&F15,AuxData!$X:$X,AuxData!$Y:$Y))) | H15: =IF(I15="Y","Inner","") -> Inner | I15: =IF(ISERROR(MATCH($E15,'3. Data Sources'!$B$5:$B$210,0)),"ERROR",LOOKUP($E15,'3. Data Sources'!$B$5:$B$210,'3. Data Sources'!$E$5:$E$210)) -> Y | J15: Left Outer
B16: ENR_RADIO_5G_GNODEB | C16: NE_NAME | D16: =IF(ISERROR(MATCH(B16&"_"&C16,AuxData!$X:$X,0)),"",IF(LOOKUP(B16&"_"&C16,AuxData!$X:$X,AuxData!$Y:$Y)="","Not defined",LOOKUP(B16&"_"&C16,AuxData!$X:$X,AuxData!$Y:$Y))) -> NE_NAME | E16: T1593835529_5G | F16: Object | G16: =IF(ISERROR(MATCH(E16&"_"&F16,AuxData!$X:$X,0)),"",IF(LOOKUP(E16&"_"&F16,AuxData!$X:$X,AuxData!$Y:$Y)="","Not defined",LOOKUP(E16&"_"&F16,AuxData!$X:$X,AuxData!$Y:$Y))) -> OBJECT | H16: =IF(I16="Y","Inner","") -> Inner | I16: =IF(ISERROR(MATCH($E16,'3. Data Sources'!$B$5:$B$210,0)),"ERROR",LOOKUP($E16,'3. Data Sources'!$B$5:$B$210,'3. Data Sources'!$E$5:$E$210)) -> Y | J16: Left Outer
B17: ENR_RADIO_5G_GNODEB | C17: NE_NAME | D17: =IF(ISERROR(MATCH(B17&"_"&C17,AuxData!$X:$X,0)),"",IF(LOOKUP(B17&"_"&C17,AuxData!$X:$X,AuxData!$Y:$Y)="","Not defined",LOOKUP(B17&"_"&C17,AuxData!$X:$X,AuxData!$Y:$Y))) -> NE_NAME | E17: T1593835531_5G | F17: Object | G17: =IF(ISERROR(MATCH(E17&"_"&F17,AuxData!$X:$X,0)),"",IF(LOOKUP(E17&"_"&F17,AuxData!$X:$X,AuxData!$Y:$Y)="","Not defined",LOOKUP(E17&"_"&F17,AuxData!$X:$X,AuxData!$Y:$Y))) -> OBJECT | H17: =IF(I17="Y","Inner","") -> Inner | I17: =IF(ISERROR(MATCH($E17,'3. Data Sources'!$B$5:$B$210,0)),"ERROR",LOOKUP($E17,'3. Data Sources'!$B$5:$B$210,'3. Data Sources'!$E$5:$E$210)) -> Y | J17: Left Outer
... B36: ENR_RADIO_5G_CELLS | C36: INVCELL | D36: =IF(ISERROR(MATCH(B36&"_"&C36,AuxData!$X:$X,0)),"",IF(LOOKUP(B36&"_"&C36,AuxData!$X:$X,AuxData!$Y:$Y)="","Not defined",LOOKUP(B36&"_"&C36,AuxData!$X:$X,AuxData!$Y:$Y))) -> INVCELL | E36: T1911816269 | F36: INVCELL | G36: =IF(ISERROR(MATCH(E36&"_"&F36,AuxData!$X:$X,0)),"",IF(LOOKUP(E36&"_"&F36,AuxData!$X:$X,AuxData!$Y:$Y)="","Not defined",LOOKUP(E36&"_"&F36,AuxData!$X:$X,AuxData!$Y:$Y))) -> INVCELL | H36: =IF(I36="Y","Inner","") -> Inner | I36: =IF(ISERROR(MATCH($E36,'3. Data Sources'!$B$5:$B$210,0)),"ERROR",LOOKUP($E36,'3. Data Sources'!$B$5:$B$210,'3. Data Sources'!$E$5:$E$210)) -> Y | J36: Left Outer
B37: ENR_RADIO_5G_CELLS | C37: INVCELL | D37: =IF(ISERROR(MATCH(B37&"_"&C37,AuxData!$X:$X,0)),"",IF(LOOKUP(B37&"_"&C37,AuxData!$X:$X,AuxData!$Y:$Y)="","Not defined",LOOKUP(B37&"_"&C37,AuxData!$X:$X,AuxData!$Y:$Y))) -> INVCELL | E37: T1911816271_CQI1 | F37: INVCELL | G37: =IF(ISERROR(MATCH(E37&"_"&F37,AuxData!$X:$X,0)),"",IF(LOOKUP(E37&"_"&F37,AuxData!$X:$X,AuxData!$Y:$Y)="","Not defined",LOOKUP(E37&"_"&F37,AuxData!$X:$X,AuxData!$Y:$Y))) -> INVCELL | H37: Inner | I37: =IF(ISERROR(MATCH($E37,'3. Data Sources'!$B$5:$B$210,0)),"ERROR",LOOKUP($E37,'3. Data Sources'!$B$5:$B$210,'3. Data Sources'!$E$5:$E$210)) -> Y | J37: Left Outer
B38: ENR_RADIO_5G_CELLS | C38: INVCELL | D38: =IF(ISERROR(MATCH(B38&"_"&C38,AuxData!$X:$X,0)),"",IF(LOOKUP(B38&"_"&C38,AuxData!$X:$X,AuxData!$Y:$Y)="","Not defined",LOOKUP(B38&"_"&C38,AuxData!$X:$X,AuxData!$Y:$Y))) -> INVCELL | E38: T1911816271_CQI5 | F38: INVCELL | G38: =IF(ISERROR(MATCH(E38&"_"&F38,AuxData!$X:$X,0)),"",IF(LOOKUP(E38&"_"&F38,AuxData!$X:$X,AuxData!$Y:$Y)="","Not defined",LOOKUP(E38&"_"&F38,AuxData!$X:$X,AuxData!$Y:$Y))) -> INVCELL | H38: Inner | I38: =IF(ISERROR(MATCH($E38,'3. Data Sources'!$B$5:$B$210,0)),"ERROR",LOOKUP($E38,'3. Data Sources'!$B$5:$B$210,'3. Data Sources'!$E$5:$E$210)) -> Y | J38: Left Outer
B39: ENR_RADIO_5G_CELLS | C39: INVCELL | D39: =IF(ISERROR(MATCH(B39&"_"&C39,AuxData!$X:$X,0)),"",IF(LOOKUP(B39&"_"&C39,AuxData!$X:$X,AuxData!$Y:$Y)="","Not defined",LOOKUP(B39&"_"&C39,AuxData!$X:$X,AuxData!$Y:$Y))) -> INVCELL | E39: T1911816271_CQI9 | F39: INVCELL | G39: =IF(ISERROR(MATCH(E39&"_"&F39,AuxData!$X:$X,0)),"",IF(LOOKUP(E39&"_"&F39,AuxData!$X:$X,AuxData!$Y:$Y)="","Not defined",LOOKUP(E39&"_"&F39,AuxData!$X:$X,AuxData!$Y:$Y))) -> INVCELL | H39: Inner | I39: =IF(ISERROR(MATCH($E39,'3. Data Sources'!$B$5:$B$210,0)),"ERROR",LOOKUP($E39,'3. Data Sources'!$B$5:$B$210,'3. Data Sources'!$E$5:$E$210)) -> Y | J39: Left Outer
B40: ENR_RADIO_5G_CELLS | C40: INVCELL | D40: =IF(ISERROR(MATCH(B40&"_"&C40,AuxData!$X:$X,0)),"",IF(LOOKUP(B40&"_"&C40,AuxData!$X:$X,AuxData!$Y:$Y)="","Not defined",LOOKUP(B40&"_"&C40,AuxData!$X:$X,AuxData!$Y:$Y))) -> INVCELL | E40: T1911816273 | F40: INVCELL | G40: =IF(ISERROR(MATCH(E40&"_"&F40,AuxData!$X:$X,0)),"",IF(LOOKUP(E40&"_"&F40,AuxData!$X:$X,AuxData!$Y:$Y)="","Not defined",LOOKUP(E40&"_"&F40,AuxData!$X:$X,AuxData!$Y:$Y))) -> INVCELL | H40: =IF(I40="Y","Inner","") -> Inner | I40: =IF(ISERROR(MATCH($E40,'3. Data Sources'!$B$5:$B$210,0)),"ERROR",LOOKUP($E40,'3. Data Sources'!$B$5:$B$210,'3. Data Sources'!$E$5:$E$210)) -> Y | J40: Left Outer
B41: ENR_RADIO_5G_CELLS | C41: INVCELL | D41: =IF(ISERROR(MATCH(B41&"_"&C41,AuxData!$X:$X,0)),"",IF(LOOKUP(B41&"_"&C41,AuxData!$X:$X,AuxData!$Y:$Y)="","Not defined",LOOKUP(B41&"_"&C41,AuxData!$X:$X,AuxData!$Y:$Y))) -> INVCELL | E41: T1911816274 | F41: INVCELL | G41: =IF(ISERROR(MATCH(E41&"_"&F41,AuxData!$X:$X,0)),"",IF(LOOKUP(E41&"_"&F41,AuxData!$X:$X,AuxData!$Y:$Y)="","Not defined",LOOKUP(E41&"_"&F41,AuxData!$X:$X,AuxData!$Y:$Y))) -> INVCELL | H41: =IF(I41="Y","Inner","") -> Inner | I41: =IF(ISERROR(MATCH($E41,'3. Data Sources'!$B$5:$B$210,0)),"ERROR",LOOKUP($E41,'3. Data Sources'!$B$5:$B$210,'3. Data Sources'!$E$5:$E$210)) -> Y | J41: Left Outer
B42: ENR_RADIO_5G_CELLS | C42: INVCELL | D42: =IF(ISERROR(MATCH(B42&"_"&C42,AuxData!$X:$X,0)),"",IF(LOOKUP(B42&"_"&C42,AuxData!$X:$X,AuxData!$Y:$Y)="","Not defined",LOOKUP(B42&"_"&C42,AuxData!$X:$X,AuxData!$Y:$Y))) -> INVCELL | E42: T1911816277 | F42: INVCELL | G42: =IF(ISERROR(MATCH(E42&"_"&F42,AuxData!$X:$X,0)),"",IF(LOOKUP(E42&"_"&F42,AuxData!$X:$X,AuxData!$Y:$Y)="","Not defined",LOOKUP(E42&"_"&F42,AuxData!$X:$X,AuxData!$Y:$Y))) -> INVCELL | H42: =IF(I42="Y","Inner","") -> Inner | I42: =IF(ISERROR(MATCH($E42,'3. Data Sources'!$B$5:$B$210,0)),"ERROR",LOOKUP($E42,'3. Data Sources'!$B$5:$B$210,'3. Data Sources'!$E$5:$E$210)) -> Y | J42: Left Outer
B43: ENR_RADIO_5G_CELLS | C43: INVCELL | D43: =IF(ISERROR(MATCH(B43&"_"&C43,AuxData!$X:$X,0)),"",IF(LOOKUP(B43&"_"&C43,AuxData!$X:$X,AuxData!$Y:$Y)="","Not defined",LOOKUP(B43&"_"&C43,AuxData!$X:$X,AuxData!$Y:$Y))) -> INVCELL | E43: T1911816281 | F43: INVCELL | G43: =IF(ISERROR(MATCH(E43&"_"&F43,AuxData!$X:$X,0)),"",IF(LOOKUP(E43&"_"&F43,AuxData!$X:$X,AuxData!$Y:$Y)="","Not defined",LOOKUP(E43&"_"&F43,AuxData!$X:$X,AuxData!$Y:$Y))) -> INVCELL | H43: =IF(I43="Y","Inner","") -> Inner | I43: =IF(ISERROR(MATCH($E43,'3. Data Sources'!$B$5:$B$210,0)),"ERROR",LOOKUP($E43,'3. Data Sources'!$B$5:$B$210,'3. Data Sources'!$E$5:$E$210)) -> Y | J43: Left Outer
B44: ENR_RADIO_5G_CELLS | C44: INVCELL | D44: =IF(ISERROR(MATCH(B44&"_"&C44,AuxData!$X:$X,0)),"",IF(LOOKUP(B44&"_"&C44,AuxData!$X:$X,AuxData!$Y:$Y)="","Not defined",LOOKUP(B44&"_"&C44,AuxData!$X:$X,AuxData!$Y:$Y))) -> INVCELL | E44: T1911816285 | F44: INVCELL | G44: =IF(ISERROR(MATCH(E44&"_"&F44,AuxData!$X:$X,0)),"",IF(LOOKUP(E44&"_"&F44,AuxData!$X:$X,AuxData!$Y:$Y)="","Not defined",LOOKUP(E44&"_"&F44,AuxData!$X:$X,AuxData!$Y:$Y))) -> INVCELL | H44: =IF(I44="Y","Inner","") -> Inner | I44: =IF(ISERROR(MATCH($E44,'3. Data Sources'!$B$5:$B$210,0)),"ERROR",LOOKUP($E44,'3. Data Sources'!$B$5:$B$210,'3. Data Sources'!$E$5:$E$210)) -> Y | J44: Left Outer
B45: ENR_RADIO_5G_CELLS | C45: INVCELL | D45: =IF(ISERROR(MATCH(B45&"_"&C45,AuxData!$X:$X,0)),"",IF(LOOKUP(B45&"_"&C45,AuxData!$X:$X,AuxData!$Y:$Y)="","Not defined",LOOKUP(B45&"_"&C45,AuxData!$X:$X,AuxData!$Y:$Y))) -> INVCELL | E45: T1911816286 | F45: INVCELL | G45: =IF(ISERROR(MATCH(E45&"_"&F45,AuxData!$X:$X,0)),"",IF(LOOKUP(E45&"_"&F45,AuxData!$X:$X,AuxData!$Y:$Y)="","Not defined",LOOKUP(E45&"_"&F45,AuxData!$X:$X,AuxData!$Y:$Y))) -> INVCELL | H45: =IF(I45="Y","Inner","") -> Inner | I45: =IF(ISERROR(MATCH($E45,'3. Data Sources'!$B$5:$B$210,0)),"ERROR",LOOKUP($E45,'3. Data Sources'!$B$5:$B$210,'3. Data Sources'!$E$5:$E$210)) -> Y | J45: Left Outer
B46: ENR_RADIO_5G_CELLS | C46: INVCELL | D46: =IF(ISERROR(MATCH(B46&"_"&C46,AuxData!$X:$X,0)),"",IF(LOOKUP(B46&"_"&C46,AuxData!$X:$X,AuxData!$Y:$Y)="","Not defined",LOOKUP(B46&"_"&C46,AuxData!$X:$X,AuxData!$Y:$Y))) -> INVCELL | E46: T1911816287 | F46: INVCELL | G46: =IF(ISERROR(MATCH(E46&"_"&F46,AuxData!$X:$X,0)),"",IF(LOOKUP(E46&"_"&F46,AuxData!$X:$X,AuxData!$Y:$Y)="","Not defined",LOOKUP(E46&"_"&F46,AuxData!$X:$X,AuxData!$Y:$Y))) -> INVCELL | H46: =IF(I46="Y","Inner","") -> Inner | I46: =IF(ISERROR(MATCH($E46,'3. Data Sources'!$B$5:$B$210,0)),"ERROR",LOOKUP($E46,'3. Data Sources'!$B$5:$B$210,'3. Data Sources'!$E$5:$E$210)) -> Y | J46: Left Outer
B47: ENR_RADIO_5G_CELLS | C47: INVCELL | D47: =IF(ISERROR(MATCH(B47&"_"&C47,AuxData!$X:$X,0)),"",IF(LOOKUP(B47&"_"&C47,AuxData!$X:$X,AuxData!$Y:$Y)="","Not defined",LOOKUP(B47&"_"&C47,AuxData!$X:$X,AuxData!$Y:$Y))) -> INVCELL | E47: T1911816292 | F47: INVCELL | G47: =IF(ISERROR(MATCH(E47&"_"&F47,AuxData!$X:$X,0)),"",IF(LOOKUP(E47&"_"&F47,AuxData!$X:$X,AuxData!$Y:$Y)="","Not defined",LOOKUP(E47&"_"&F47,AuxData!$X:$X,AuxData!$Y:$Y))) -> INVCELL | H47: =IF(I47="Y","Inner","") -> Inner | I47: =IF(ISERROR(MATCH($E47,'3. Data Sources'!$B$5:$B$210,0)),"ERROR",LOOKUP($E47,'3. Data Sources'!$B$5:$B$210,'3. Data Sources'!$E$5:$E$210)) -> Y | J47: Left Outer
B48: ENR_RADIO_5G_CELLS | C48: INVCELL | D48: =IF(ISERROR(MATCH(B48&"_"&C48,AuxData!$X:$X,0)),"",IF(LOOKUP(B48&"_"&C48,AuxData!$X:$X,AuxData!$Y:$Y)="","Not defined",LOOKUP(B48&"_"&C48,AuxData!$X:$X,AuxData!$Y:$Y))) -> INVCELL | E48: T1911816293 | F48: INVCELL | G48: =IF(ISERROR(MATCH(E48&"_"&F48,AuxData!$X:$X,0)),"",IF(LOOKUP(E48&"_"&F48,AuxData!$X:$X,AuxData!$Y:$Y)="","Not defined",LOOKUP(E48&"_"&F48,AuxData!$X:$X,AuxData!$Y:$Y))) -> INVCELL | H48: Inner | I48: =IF(ISERROR(MATCH($E48,'3. Data Sources'!$B$5:$B$210,0)),"ERROR",LOOKUP($E48,'3. Data Sources'!$B$5:$B$210,'3. Data Sources'!$E$5:$E$210)) -> Y | J48: Left Outer
B49: V_ENR_RADIO_5G_CELLS | C49: CELL_ID_D | D49: =IF(ISERROR(MATCH(B49&"_"&C49,AuxData!$X:$X,0)),"",IF(LOOKUP(B49&"_"&C49,AuxData!$X:$X,AuxData!$Y:$Y)="","Not defined",LOOKUP(B49&"_"&C49,AuxData!$X:$X,AuxData!$Y:$Y))) -> CELL_ID | E49: T1911816293 | F49: TargetCellID | G49: =IF(ISERROR(MATCH(E49&"_"&F49,AuxData!$X:$X,0)),"",IF(LOOKUP(E49&"_"&F49,AuxData!$X:$X,AuxData!$Y:$Y)="","Not defined",LOOKUP(E49&"_"&F49,AuxData!$X:$X,AuxData!$Y:$Y))) -> TARGETCELLID | H49: Left Outer | I49: =IF(ISERROR(MATCH($E49,'3. Data Sources'!$B$5:$B$210,0)),"ERROR",LOOKUP($E49,'3. Data Sources'!$B$5:$B$210,'3. Data Sources'!$E$5:$E$210)) -> Y | J49: Left Outer
B50: V_ENR_RADIO_5G_CELLS | C50: gNodeB_ID | D50: =IF(ISERROR(MATCH(B50&"_"&C50,AuxData!$X:$X,0)),"",IF(LOOKUP(B50&"_"&C50,AuxData!$X:$X,AuxData!$Y:$Y)="","Not defined",LOOKUP(B50&"_"&C50,AuxData!$X:$X,AuxData!$Y:$Y))) -> GNODEB_ID | E50: T1911816293 | F50: TargetgNodeBID | G50: =IF(ISERROR(MATCH(E50&"_"&F50,AuxData!$X:$X,0)),"",IF(LOOKUP(E50&"_"&F50,AuxData!$X:$X,AuxData!$Y:$Y)="","Not defined",LOOKUP(E50&"_"&F50,AuxData!$X:$X,AuxData!$Y:$Y))) -> TARGETGNODEBID | H50: Left Outer | I50: =IF(ISERROR(MATCH($E50,'3. Data Sources'!$B$5:$B$210,0)),"ERROR",LOOKUP($E50,'3. Data Sources'!$B$5:$B$210,'3. Data Sources'!$E$5:$E$210)) -> Y | J50: Left Outer
B51: ENR_RADIO_5G_CELLS | C51: INVCELL | D51: =IF(ISERROR(MATCH(B51&"_"&C51,AuxData!$X:$X,0)),"",IF(LOOKUP(B51&"_"&C51,AuxData!$X:$X,AuxData!$Y:$Y)="","Not defined",LOOKUP(B51&"_"&C51,AuxData!$X:$X,AuxData!$Y:$Y))) -> INVCELL | E51: T1911816294 | F51: INVCELL | G51: =IF(ISERROR(MATCH(E51&"_"&F51,AuxData!$X:$X,0)),"",IF(LOOKUP(E51&"_"&F51,AuxData!$X:$X,AuxData!$Y:$Y)="","Not defined",LOOKUP(E51&"_"&F51,AuxData!$X:$X,AuxData!$Y:$Y))) -> INVCELL | H51: Inner | I51: =IF(ISERROR(MATCH($E51,'3. Data Sources'!$B$5:$B$210,0)),"ERROR",LOOKUP($E51,'3. Data Sources'!$B$5:$B$210,'3. Data Sources'!$E$5:$E$210)) -> Y | J51: Left Outer
B52: ENR_OPERATORS | C52: MCC | D52: =IF(ISERROR(MATCH(B52&"_"&C52,AuxData!$X:$X,0)),"",IF(LOOKUP(B52&"_"&C52,AuxData!$X:$X,AuxData!$Y:$Y)="","Not defined",LOOKUP(B52&"_"&C52,AuxData!$X:$X,AuxData!$Y:$Y))) -> MCC | E52: T1911816294 | F52: MobileCountryCode | G52: =IF(ISERROR(MATCH(E52&"_"&F52,AuxData!$X:$X,0)),"",IF(LOOKUP(E52&"_"&F52,AuxData!$X:$X,AuxData!$Y:$Y)="","Not defined",LOOKUP(E52&"_"&F52,AuxData!$X:$X,AuxData!$Y:$Y))) -> MOBILECOUNTRYCODE | H52: Inner | I52: Y | J52: Left Outer
B53: ENR_OPERATORS | C53: MNC | D53: =IF(ISERROR(MATCH(B53&"_"&C53,AuxData!$X:$X,0)),"",IF(LOOKUP(B53&"_"&C53,AuxData!$X:$X,AuxData!$Y:$Y)="","Not defined",LOOKUP(B53&"_"&C53,AuxData!$X:$X,AuxData!$Y:$Y))) -> MNC | E53: T1911816294 | F53: MobileCountryCode | G53: =IF(ISERROR(MATCH(E53&"_"&F53,AuxData!$X:$X,0)),"",IF(LOOKUP(E53&"_"&F53,AuxData!$X:$X,AuxData!$Y:$Y)="","Not defined",LOOKUP(E53&"_"&F53,AuxData!$X:$X,AuxData!$Y:$Y))) -> MOBILECOUNTRYCODE | H53: Inner | I53: Y | J53: Left Outer
B54: ENR_RADIO_5G_CELLS | C54: INVCELL | D54: =IF(ISERROR(MATCH(B54&"_"&C54,AuxData!$X:$X,0)),"",IF(LOOKUP(B54&"_"&C54,AuxData!$X:$X,AuxData!$Y:$Y)="","Not defined",LOOKUP(B54&"_"&C54,AuxData!$X:$X,AuxData!$Y:$Y))) -> INVCELL | E54: T1911816295 | F54: INVCELL | G54: =IF(ISERROR(MATCH(E54&"_"&F54,AuxData!$X:$X,0)),"",IF(LOOKUP(E54&"_"&F54,AuxData!$X:$X,AuxData!$Y:$Y)="","Not defined",LOOKUP(E54&"_"&F54,AuxData!$X:$X,AuxData!$Y:$Y))) -> INVCELL | H54: Inner | I54: =IF(ISERROR(MATCH($E54,'3. Data Sources'!$B$5:$B$210,0)),"ERROR",LOOKUP($E54,'3. Data Sources'!$B$5:$B$210,'3. Data Sources'!$E$5:$E$210)) -> Y | J54: Left Outer
